Workbook

Sheet Groundwater Discharge Permi
A1: X | B1: Y | C1: NPDES Number | D1: Permit Number | E1: Facility Name
A2: -8542729.2 | B2: 4780067.6 | C2: MD3841C16 | D2: 18CT3841 | E2: 2704 SH, LLC
A3: -8602880.3 | B3: 4771694.7 | C3: MD2972K04 | D3: 23DP2972 | E3: A T & T - Monrovia
A4: -8531987.1 | B4: 4752521.6 | C4: MD0064B23 | D4: 21VW0064 | E4: A-1 AUTO BODY
A5: -8444032.4 | B5: 4757859.7 | C5: MD3669R15 | D5: 21DP3669 | E5: AIS Enclosure Systems LLC
A6: -8518628.6 | B6: 4763836.2 | C6: MD0065B23 | D6: 21VW0065 | E6: All About Pressure Washing
A7: -8537963.3 | B7: 4694709.1 | C7: MD0077B24 | D7: 21VW0077 | E7: All American Ambulance
A8: -8564269.5 | B8: 4746175.6 | C8: MD3102N06 | D8: 19DP3102 | E8: Ashleigh Knolls Subdivision
A9: -8474481.4 | B9: 4710206.6 | C9: MD3786R13 | D9: 20DP3786 | E9: Aspen Institute
A10: -8366316 | B10: 4614665.1 | C10: MD3453X03 | D10: 21VW3453 | E10: Assateague Island-National Seashore WWTP
A11: -8365215.9 | B11: 4621404.5 | C11: MD2608X06 | D11: 24DP2608 | E11: Assateague Pointe Lagoon-WWTL
A12: -8414672.5 | B12: 4590849 | C12: MD0009X20 | D12: 21VW0009 | E12: Atlantic Tractor, LLC
A13: -8514940.7 | B13: 4722488.5 | C13: MD3390B02 | D13: 25DP3390 | E13: Atria Manresa Nursing Home
... A212: -8556306.8 | B212: 4661055.3 | C212: MD3871I21 | D212: 21DP3871 | E212: Wintergreen Corner

Sheet Sheet3
A1: addr | B1: city | C1: lat | D1: long
A2: 8804 Logtown rd | B2: Berlin | C2: 38.360057, -75.266878
A3: 12801 Stone Hill Road | B3: Phoenix | C3: 39.475035, -76.557204
A4: 17301 York Road | B4: Parkton | C4: 39.599319, -76.659563
A5: 4472 Gallant Green Road | B5: Waldorf | C5: 38.588658, -76.793209
A6: 310 Bateau Dr | B6: Stevensville | C6: 38.984934, -76.324778
A7: 3151 Presidential Golf Drive | B7: Upper Marlboro | C7: 38.846640, -76.733352
A8: 3212 Snake Ln | B8: Churchville | C8: 39.538370, -76.238873
A9: 3499 Sweet Air Rd | B9: Phoenix | C9: 39.515258, -76.557654
A10: 5018 Mountain Rd | B10: Pasadena | C10: 39.102963, -76.433207
A11: 9035 Ironsides Rd | B11: Nanjemoy | C11: 38.464701, -77.168127
A12: 3940 Nassawango Rd | B12: Snow Hill | C12: 38.141879, -75.463354
A13: Madeline Circle | B13: Parsonsburg | C13: 38.396186, -75.456401
... A21: 5405 Leonardtown Road | B21: Waldorf | C21: 38.575560, -76.862612

Sheet Sheet1
A1: npdes.id | B1: name | C1: missing
A2: MD3861O18 | B2: =_xlfn.XLOOKUP(A2,'Groundwater Discharge Permi'!C$2:C$193,'Groundwater Discharge Permi'!E$2:E$193, "NA") -> Bay Shore Campground
A3: MD3102N06 | B3: =_xlfn.XLOOKUP(A3,'Groundwater Discharge Permi'!C$2:C$193,'Groundwater Discharge Permi'!E$2:E$193, "NA") -> Ashleigh Knolls Subdivision
A4: MD3786R13 | B4: =_xlfn.XLOOKUP(A4,'Groundwater Discharge Permi'!C$2:C$193,'Groundwater Discharge Permi'!E$2:E$193, "NA") -> Aspen Institute
A5: MD2608X06 | B5: =_xlfn.XLOOKUP(A5,'Groundwater Discharge Permi'!C$2:C$193,'Groundwater Discharge Permi'!E$2:E$193, "NA") -> Assateague Pointe Lagoon-WWTL
A6: MD2972K04 | B6: =_xlfn.XLOOKUP(A6,'Groundwater Discharge Permi'!C$2:C$193,'Groundwater Discharge Permi'!E$2:E$193, "NA") -> A T & T - Monrovia
A7: MD3457K04 | B7: =_xlfn.XLOOKUP(A7,'Groundwater Discharge Permi'!C$2:C$193,'Groundwater Discharge Permi'!E$2:E$193, "NA") -> Mountainside Day Camp
A8: MD3811J14 | B8: =_xlfn.XLOOKUP(A8,'Groundwater Discharge Permi'!C$2:C$193,'Groundwater Discharge Permi'!E$2:E$193, "NA") -> Beaver Run Mobile Home Park
A9: MD2864X91 | B9: =_xlfn.XLOOKUP(A9,'Groundwater Discharge Permi'!C$2:C$193,'Groundwater Discharge Permi'!E$2:E$193, "NA") -> Berlin WWTP - Spray Irrigation Site
A10: MD2806D01 | B10: =_xlfn.XLOOKUP(A10,'Groundwater Discharge Permi'!C$2:C$193,'Groundwater Discharge Permi'!E$2:E$193, "NA") -> Constellation Power - Notch Cliff
A11: MD0284J06 | B11: =_xlfn.XLOOKUP(A11,'Groundwater Discharge Permi'!C$2:C$193,'Groundwater Discharge Permi'!E$2:E$193, "NA") -> Black Gold Farms
A12: MD3295P05 | B12: =_xlfn.XLOOKUP(A12,'Groundwater Discharge Permi'!C$2:C$193,'Groundwater Discharge Permi'!E$2:E$193, "NA") -> Blue Mash Golf Course
A13: MD3528H05 | B13: =_xlfn.XLOOKUP(A13,'Groundwater Discharge Permi'!C$2:C$193,'Groundwater Discharge Permi'!E$2:E$193, "NA") -> Bohemia Bay Yacht Harbor
... A43: MD2722J07 | B43: =_xlfn.XLOOKUP(A43,'Groundwater Discharge Permi'!C$2:C$193,'Groundwater Discharge Permi'!E$2:E$193, "NA") -> Deep Water Subdivision - Phase II
A44: MD3683X15 | B44: =_xlfn.XLOOKUP(A44,'Groundwater Discharge Permi'!C$2:C$193,'Groundwater Discharge Permi'!E$2:E$193, "NA") -> NA | C44: Deer Run Campground - Logtown Road LLC
A45: MD3220X03 | B45: =_xlfn.XLOOKUP(A45,'Groundwater Discharge Permi'!C$2:C$193,'Groundwater Discharge Permi'!E$2:E$193, "NA") -> Deer Run Golf Club
A46: MD3436C03 | B46: =_xlfn.XLOOKUP(A46,'Groundwater Discharge Permi'!C$2:C$193,'Groundwater Discharge Permi'!E$2:E$193, "NA") -> NA | C46: Eagle's Nest Country Club
A47: MD3886U22 | B47: =_xlfn.XLOOKUP(A47,'Groundwater Discharge Permi'!C$2:C$193,'Groundwater Discharge Permi'!E$2:E$193, "NA") -> Easton Utilities - N Washington St
A48: MD3435N03 | B48: =_xlfn.XLOOKUP(A48,'Groundwater Discharge Permi'!C$2:C$193,'Groundwater Discharge Permi'!E$2:E$193, "NA") -> Ellicott Meadows Community WWTP
A49: MD3492G04 | B49: =_xlfn.XLOOKUP(A49,'Groundwater Discharge Permi'!C$2:C$193,'Groundwater Discharge Permi'!E$2:E$193, "NA") -> ESAB Welding & Cutting Products
A50: MD3370B06 | B50: =_xlfn.XLOOKUP(A50,'Groundwater Discharge Permi'!C$2:C$193,'Groundwater Discharge Permi'!E$2:E$193, "NA") -> Evangelical Presbyterian Church of Annapolis
A51: MD3370B06 | B51: =_xlfn.XLOOKUP(A51,'Groundwater Discharge Permi'!C$2:C$193,'Groundwater Discharge Permi'!E$2:E$193, "NA") -> Evangelical Presbyterian Church of Annapolis
A52: MD3663M09 | B52: =_xlfn.XLOOKUP(A52,'Groundwater Discharge Permi'!C$2:C$193,'Groundwater Discharge Permi'!E$2:E$193, "NA") -> Fallston High School
A53: MD3209V02 | B53: =_xlfn.XLOOKUP(A53,'Groundwater Discharge Permi'!C$2:C$193,'Groundwater Discharge Permi'!E$2:E$193, "NA") -> F.A.A. Remote Transmitter Site
A54: MD2820J09 | B54: =_xlfn.XLOOKUP(A54,'Groundwater Discharge Permi'!C$2:C$193,'Groundwater Discharge Permi'!E$2:E$193, "NA") -> Ferry Farms Estates - Phase I
A55: MD2821J09 | B55: =_xlfn.XLOOKUP(A55,'Groundwater Discharge Permi'!C$2:C$193,'Groundwater Discharge Permi'!E$2:E$193, "NA") -> Ferry Farms Estates - Phase II
A56: MD3280T09 | B56: =_xlfn.XLOOKUP(A56,'Groundwater Discharge Permi'!C$2:C$193,'Groundwater Discharge Permi'!E$2:E$193, "NA") -> Forrest Farm WWTP
A57: MD3724X17 | B57: =_xlfn.XLOOKUP(A57,'Groundwater Discharge Permi'!C$2:C$193,'Groundwater Discharge Permi'!E$2:E$193, "NA") -> Fort Whaley Campground
A58: MD3336K05 | B58: =_xlfn.XLOOKUP(A58,'Groundwater Discharge Permi'!C$2:C$193,'Groundwater Discharge Permi'!E$2:E$193, "NA") -> Frederick Christian Fellowship Church
... A67: MD3285M05 | B67: =_xlfn.XLOOKUP(A67,'Groundwater Discharge Permi'!C$2:C$193,'Groundwater Discharge Permi'!E$2:E$193, "NA") -> Harford Technical High School
A68: MD3785C13 | B68: =_xlfn.XLOOKUP(A68,'Groundwater Discharge Permi'!C$2:C$193,'Groundwater Discharge Permi'!E$2:E$193, "NA") -> NA | C68: Hereford High School
A69: MD3480K04 | B69: =_xlfn.XLOOKUP(A69,'Groundwater Discharge Permi'!C$2:C$193,'Groundwater Discharge Permi'!E$2:E$193, "NA") -> Hollow Creek Golf Club
A70: MD2801J07 | B70: =_xlfn.XLOOKUP(A70,'Groundwater Discharge Permi'!C$2:C$193,'Groundwater Discharge Permi'!E$2:E$193, "NA") -> Hurlock WWTP
A71: MD3471X04 | B71: =_xlfn.XLOOKUP(A71,'Groundwater Discharge Permi'!C$2:C$193,'Groundwater Discharge Permi'!E$2:E$193, "NA") -> Island Resort Campground
A72: MD3836I16 | B72: =_xlfn.XLOOKUP(A72,'Groundwater Discharge Permi'!C$2:C$193,'Groundwater Discharge Permi'!E$2:E$193, "NA") -> NA | C72: Keller Bus Transportation
A73: MD2885R08 | B73: =_xlfn.XLOOKUP(A73,'Groundwater Discharge Permi'!C$2:C$193,'Groundwater Discharge Permi'!E$2:E$193, "NA") -> NA | C73: Kent Narrows Water Fowl Ponds
A74: MD3741S11 | B74: =_xlfn.XLOOKUP(A74,'Groundwater Discharge Permi'!C$2:C$193,'Groundwater Discharge Permi'!E$2:E$193, "NA") -> Kuzzens Packing
A75: MD3531X06 | B75: =_xlfn.XLOOKUP(A75,'Groundwater Discharge Permi'!C$2:C$193,'Groundwater Discharge Permi'!E$2:E$193, "NA") -> Lake Haven Mobile Home Park WWTP
A76: MD3881Q23 | B76: =_xlfn.XLOOKUP(A76,'Groundwater Discharge Permi'!C$2:C$193,'Groundwater Discharge Permi'!E$2:E$193, "NA") -> NA | C76: Lake Presidential Golf Club
A77: MD3597G08 | B77: =_xlfn.XLOOKUP(A77,'Groundwater Discharge Permi'!C$2:C$193,'Groundwater Discharge Permi'!E$2:E$193, "NA") -> Lakeview Mobile Home Park
...

Sheet Sheet2
A2: Ashleigh Knolls Subdivision | B2: 7299 Fawn Crossing Dr | C2: Clarksville | D2: 19DP3102
A3: Aspen Institute | B3: 2010 Carmichael Rd | C3: Queenstown | D3: 20DP3786
A4: Assateague Pointe WWTP | B4: 11501 Assateague Way | C4: Berlin | D4: 24DP2608
A5: AT&T - Monrovia | B5: 11028 Fingerboard Road | C5: Monrovia | D5: 23DP2972
A6: Bar-T Mountainside Camp (formerly Mountainside Day Camp) | B6: 2914 Roderick Rd | C6: Frederick | D6: 18DP3457
A7: Beaver Run Mobile Home Park | B7: 3658 Karen Circle | C7: Linkwood | D7: 23DP3811
A8: Berlin WWTP | B8: 9607 Lee Rd | C8: Berlin | D8: 21DP2864
A9: BGE - Notch Cliff Propane Plant | B9: 10650 Harford Road | C9: Glen Arm | D9: 20DP2806
A10: Black Gold Farms | B10: 5616 Rhodesdale-Vienna Rd | C10: Rhodesdale | D10: 22DP0284
A11: Blue Mash Golf Course | B11: 5821 Olney-Laytonsville Road | C11: Laytonsville | D11: 22DP3295
A12: Bohemia Bay Yacht Harbour Condominium | B12: 1026 Town Point Rd | C12: Chesapeake City | D12: 25DP3528
A13: Boys School of Saint Paul's Parish | B13: 11152 Falls Rd | C13: Brooklandville | D13: 19DP3858
... A128: SHA - Keysers Ridge Shop | B128: 3876 National Pike | C128: Accident | D128: 25DP1814
A129: Shamrock Farm Race Training Facility | B129: 4926 Woodbine Road | C129: Woodbine
A130: Shoppes At Apple Greene WWTP | B130: 10105 Dunkirk Way | C130: Dunkirk | D130: 24DP3400
A131: Smithsonian Environmental Research Center | B131: 647 Contees Wharf Road | C131: Edgewater | D131: 20DP3562
A132: Solomons WWTP | B132: 500 Sweetwater Lane | C132: Lusby | D132: 23DP2178
A133: South Carroll Swim Club | B133: 1900 Liberty Road | C133: Sykesville | D133: 23DP3382
A134: Southstar Limited Partnership | B134: 2015 Industrial Dr | C134: Annapolis | D134: 20DP3687
A135: Sparrows Point Country Club | B135: 919 Wise Ave | C135: Dundalk | D135: 19DP3113
A136: St. Clement's Shores WWTP | B136: 21911 Rosebank Road | C136: Leonardtown | D136: 24DP1587
A137: Steeplechase Water Works | B137: 27691 Polo Ct | C137: Salisbury | D137: 22DP3550
A138: Sysco Eastern Maryland | B138: 33300 Peach Orchard Road | C138: Pocomoke City | D138: 20DP3121
A139: Talbot County Bio-Solids Utilization Facility | B139: 9786 Klondike Road | C139: Easton | D139: 24DP3763
A140: The Arena Health Club | B140: 2304 Churchville Road | C140: Bel Air | D140: 21DP3414
A141: The Arena Health Club | B141: 2304 Churchville Road | C141: Bel Air | D141: 21DP3414A
... A166: Youth's Benefit Elementary School | B166: 1901 Fallston Road | C166: Fallston | D166: 25DP3690
